Traceback (most recent call last):
  File "/home/sean/python-enviros/jupyter/lib/python3.11/site-packages/jupyter_cache/executors/utils.py", line 58, in single_nb_execution
    executenb(
  File "/home/sean/python-enviros/jupyter/lib/python3.11/site-packages/nbclient/client.py", line 1305, in execute
    return NotebookClient(nb=nb, resources=resources, km=km, **kwargs).execute()
           ^^^^^^^^^^^^^^^^^^^^^^^^^^^^^^^^^^^^^^^^^^^^^^^^^^^^^^^^^^^^^^^^^^^^^
  File "/home/sean/python-enviros/jupyter/lib/python3.11/site-packages/jupyter_core/utils/__init__.py", line 166, in wrapped
    return loop.run_until_complete(inner)
           ^^^^^^^^^^^^^^^^^^^^^^^^^^^^^^
  File "/usr/lib/python3.11/asyncio/base_events.py", line 653, in run_until_complete
    return future.result()
           ^^^^^^^^^^^^^^^
  File "/home/sean/python-enviros/jupyter/lib/python3.11/site-packages/nbclient/client.py", line 705, in async_execute
    await self.async_execute_cell(
  File "/home/sean/python-enviros/jupyter/lib/python3.11/site-packages/nbclient/client.py", line 1058, in async_execute_cell
    await self._check_raise_for_error(cell, cell_index, exec_reply)
  File "/home/sean/python-enviros/jupyter/lib/python3.11/site-packages/nbclient/client.py", line 914, in _check_raise_for_error
    raise CellExecutionError.from_cell_and_msg(cell, exec_reply_content)
nbclient.exceptions.CellExecutionError: An error occurred while executing the following cell:
------------------
y_exact = g(x)
y_euler = odeEuler(f,y0,x)
plt.plot(x,y_euler,'b.-',x,y_exact,'r-')
plt.legend(['Euler','Exact'])
plt.axis([0,2,0,2])
plt.grid(True)
plt.show()
------------------


[0;31m---------------------------------------------------------------------------[0m
[0;31mAttributeError[0m                            Traceback (most recent call last)
[0;31mAttributeError[0m: 'Mul' object has no attribute 'exp'

The above exception was the direct cause of the following exception:

[0;31mTypeError[0m                                 Traceback (most recent call last)
Cell [0;32mIn[6], line 1[0m
[0;32m----> 1[0m y_exact [38;5;241m=[39m [43mg[49m[43m([49m[43mx[49m[43m)[49m
[1;32m      2[0m y_euler [38;5;241m=[39m odeEuler(f,y0,x)
[1;32m      3[0m plt[38;5;241m.[39mplot(x,y_euler,[38;5;124m'[39m[38;5;124mb.-[39m[38;5;124m'[39m,x,y_exact,[38;5;124m'[39m[38;5;124mr-[39m[38;5;124m'[39m)

Cell [0;32mIn[5], line 5[0m, in [0;36mg[0;34m(x)[0m
[1;32m      4[0m [38;5;28;01mdef[39;00m [38;5;21mg[39m(x):
[0;32m----> 5[0m     [38;5;28;01mreturn[39;00m ([38;5;241m2[39m[38;5;241m/[39m[38;5;241m3[39m)[38;5;241m*[39mx[38;5;241m-[39m[38;5;241m2[39m[38;5;241m/[39m[38;5;241m9[39m[38;5;241m+[39m([38;5;241m2[39m[38;5;241m/[39m[38;5;241m9[39m)[38;5;241m*[39m[43mnp[49m[38;5;241;43m.[39;49m[43mexp[49m[43m([49m[38;5;241;43m-[39;49m[38;5;241;43m3[39;49m[38;5;241;43m*[39;49m[43mx[49m[43m)[49m

[0;31mTypeError[0m: loop of ufunc does not support argument 0 of type Mul which has no callable exp method

